<?xml version="1.0" encoding="utf-8"?>
<!-- This URDF was automatically created by SolidWorks to URDF Exporter! Originally created by Stephen Brawner (brawner@gmail.com) 
     Commit Version: 1.5.1-0-g916b5db  Build Version: 1.5.7152.31018
     For more information, please see http://wiki.ros.org/sw_urdf_exporter -->
<robot
  name="learm">
  <link
    name="base_link">
    <inertial>
      <origin
        xyz="2.46385234278233E-06 0.0254977101978869 0.0305564348386512"
        rpy="0 0 0" />
      <mass
        value="0.176197132421601" />
      <inertia
        ixx="0.000798111880813399"
        ixy="8.18703863042188E-08"
        ixz="-3.94345335858399E-08"
        iyy="0.000317952999154047"
        iyz="0.000127554150577539"
        izz="0.000842638582997675" />
    </inertial>
    <visual>
      <origin
        xyz="0 0 0"
        rpy="0 0 0" />
      <geometry>
        <mesh
          filename="package://learm/meshes/base_link.STL" />
      </geometry>
      <material
        name="">
        <color
          rgba="0.949019607843137 0.756862745098039 0.176470588235294 1" />
      </material>
    </visual>
    <collision>
      <origin
        xyz="0 0 0"
        rpy="0 0 0" />
      <geometry>
        <mesh
          filename="package://learm/meshes/base_link.STL" />
      </geometry>
    </collision>
  </link>
  <link
    name="link0">
    <inertial>
      <origin
        xyz="0.00224451522425875 1.05560671155303E-05 0.0154944104510827"
        rpy="0 0 0" />
      <mass
        value="0.0286579374199143" />
      <inertia
        ixx="5.30819404271102E-06"
        ixy="-5.57403498243757E-08"
        ixz="-8.07425945645655E-08"
        iyy="4.98912764783298E-06"
        iyz="7.1669375998036E-09"
        izz="7.58530025869638E-06" />
    </inertial>
    <visual>
      <origin
        xyz="0 0 0"
        rpy="0 0 0" />
      <geometry>
        <mesh
          filename="package://learm/meshes/link0.STL" />
      </geometry>
      <material
        name="">
        <color
          rgba="0.0980392156862745 0.0980392156862745 0.0980392156862745 1" />
      </material>
    </visual>
    <collision>
      <origin
        xyz="0 0 0"
        rpy="0 0 0" />
      <geometry>
        <mesh
          filename="package://learm/meshes/link0.STL" />
      </geometry>
    </collision>
  </link>
  <joint
    name="joint0"
    type="revolute">
    <origin
      xyz="0 0 0.06975"
      rpy="0 0 0" />
    <parent
      link="base_link" />
    <child
      link="link0" />
    <axis
      xyz="0 0 1" />
    <limit
      lower="-1.5707"
      upper="1.5707"
      effort="0"
      velocity="0" />
  </joint>
  <link
    name="link1">
    <inertial>
      <origin
        xyz="0.0275226686028054 2.76349857442071E-08 0.0506788490450543"
        rpy="0 0 0" />
      <mass
        value="0.0198914095629365" />
      <inertia
        ixx="2.4862063128422E-05"
        ixy="-1.3973420479877E-11"
        ixz="3.27759383965303E-07"
        iyy="3.56469935700131E-05"
        iyz="2.77403946125307E-11"
        izz="1.2698275334445E-05" />
    </inertial>
    <visual>
      <origin
        xyz="0 0 0"
        rpy="0 0 0" />
      <geometry>
        <mesh
          filename="package://learm/meshes/link1.STL" />
      </geometry>
      <material
        name="">
        <color
          rgba="0.776470588235294 0.756862745098039 0.737254901960784 1" />
      </material>
    </visual>
    <collision>
      <origin
        xyz="0 0 0"
        rpy="0 0 0" />
      <geometry>
        <mesh
          filename="package://learm/meshes/link1.STL" />
      </geometry>
    </collision>
  </link>
  <joint
    name="joint1"
    type="revolute">
    <origin
      xyz="-0.02654 -0.01 0.01675"
      rpy="0 0 0" />
    <parent
      link="link0" />
    <child
      link="link1" />
    <axis
      xyz="1 0 0" />
    <limit
      lower="-1.5707"
      upper="1.5707"
      effort="0"
      velocity="0" />
  </joint>
  <link
    name="link2">
    <inertial>
      <origin
        xyz="0.0284558473177446 -1.29064357335118E-05 0.0232660143335079"
        rpy="0 0 0" />
      <mass
        value="0.0372957268851749" />
      <inertia
        ixx="2.59024674914256E-05"
        ixy="1.06704891430267E-08"
        ixz="8.6438772085229E-08"
        iyy="3.32187396891831E-05"
        iyz="3.14040378575013E-08"
        izz="1.02627810402537E-05" />
    </inertial>
    <visual>
      <origin
        xyz="0 0 0"
        rpy="0 0 0" />
      <geometry>
        <mesh
          filename="package://learm/meshes/link2.STL" />
      </geometry>
      <material
        name="">
        <color
          rgba="1 1 1 1" />
      </material>
    </visual>
    <collision>
      <origin
        xyz="0 0 0"
        rpy="0 0 0" />
      <geometry>
        <mesh
          filename="package://learm/meshes/link2.STL" />
      </geometry>
    </collision>
  </link>
  <joint
    name="joint2"
    type="revolute">
    <origin
      xyz="0 0 0.104"
      rpy="0 0 0" />
    <parent
      link="link1" />
    <child
      link="link2" />
    <axis
      xyz="1 0 0" />
    <limit
      lower="-1.5707"
      upper="1.5707"
      effort="0"
      velocity="0" />
  </joint>
  <link
    name="link3">
    <inertial>
      <origin
        xyz="0.0243156083533052 -0.0122137148801495 0.0184633293651139"
        rpy="0 0 0" />
      <mass
        value="0.0472722783317493" />
      <inertia
        ixx="2.80012896238471E-05"
        ixy="-1.52529513704683E-07"
        ixz="3.37277771249749E-07"
        iyy="2.31249789189803E-05"
        iyz="-2.5459200196579E-07"
        izz="1.41850933655321E-05" />
    </inertial>
    <visual>
      <origin
        xyz="0 0 0"
        rpy="0 0 0" />
      <geometry>
        <mesh
          filename="package://learm/meshes/link3.STL" />
      </geometry>
      <material
        name="">
        <color
          rgba="0.647058823529412 0.619607843137255 0.588235294117647 1" />
      </material>
    </visual>
    <collision>
      <origin
        xyz="0 0 0"
        rpy="0 0 0" />
      <geometry>
        <mesh
          filename="package://learm/meshes/link3.STL" />
      </geometry>
    </collision>
  </link>
  <joint
    name="joint3"
    type="revolute">
    <origin
      xyz="-0.0022101 0 0.08852"
      rpy="0 0 0" />
    <parent
      link="link2" />
    <child
      link="link3" />
    <axis
      xyz="1 0 0" />
    <limit
      lower="-1.5707"
      upper="1.5707"
      effort="0"
      velocity="0" />
  </joint>
  <link
    name="link4">
    <inertial>
      <origin
        xyz="-0.00298984315298845 -0.0136007289794491 0.0276531727170283"
        rpy="0 0 0" />
      <mass
        value="0.0184895230633081" />
      <inertia
        ixx="6.15016737206511E-06"
        ixy="-3.09749389160039E-07"
        ixz="1.77330393858005E-07"
        iyy="5.93857964470286E-06"
        iyz="7.20913343527975E-07"
        izz="7.36450564297619E-06" />
    </inertial>
    <visual>
      <origin
        xyz="0 0 0"
        rpy="0 0 0" />
      <geometry>
        <mesh
          filename="package://learm/meshes/link4.STL" />
      </geometry>
      <material
        name="">
        <color
          rgba="0.298039215686275 0.298039215686275 0.298039215686275 1" />
      </material>
    </visual>
    <collision>
      <origin
        xyz="0 0 0"
        rpy="0 0 0" />
      <geometry>
        <mesh
          filename="package://learm/meshes/link4.STL" />
      </geometry>
    </collision>
  </link>
  <joint
    name="joint4"
    type="revolute">
    <origin
      xyz="0.025281 -0.0007415 0.061651"
      rpy="0 0 0" />
    <parent
      link="link3" />
    <child
      link="link4" />
    <axis
      xyz="0 0 -1" />
    <limit
      lower="-1.5707"
      upper="1.5707"
      effort="0"
      velocity="0" />
  </joint>
  <link
    name="eef_link">
    <inertial>
      <origin
        xyz="0.0172496273570638 0.000188502452931755 -0.0479247481992731"
        rpy="0 0 0" />
      <mass
        value="0.011340100943172" />
      <inertia
        ixx="6.07171134981986E-06"
        ixy="-1.42687337630665E-08"
        ixz="4.87118879571211E-09"
        iyy="1.15030568612159E-05"
        iyz="4.37665366468011E-07"
        izz="5.64384752640416E-06" />
    </inertial>
    <visual>
      <origin
        xyz="0 0 0"
        rpy="0 0 0" />
      <geometry>
        <mesh
          filename="package://learm/meshes/eef_link.STL" />
      </geometry>
      <material
        name="">
        <color
          rgba="0.0980392156862745 0.0980392156862745 0.0980392156862745 1" />
      </material>
    </visual>
    <collision>
      <origin
        xyz="0 0 0"
        rpy="0 0 0" />
      <geometry>
        <mesh
          filename="package://learm/meshes/eef_link.STL" />
      </geometry>
    </collision>
  </link>
  <joint
    name="eef_joint"
    type="fixed">
    <origin
      xyz="-0.017814 0.003 0.1064"
      rpy="0 0 0" />
    <parent
      link="link4" />
    <child
      link="eef_link" />
    <axis
      xyz="0 0 0" />
  </joint>
  <link name="tool0"/>
  <joint name="tool_joint" type="fixed">
    <orignin xyz="0 0 0" rpy="0 0 0"/>
    <parent link="link4"/>
    <child link="tool0"/>
  </joint>
</robot>
